Workbook

Sheet Chris
A1: Zipper
A2: IP Address | B2: Hostname | C2: Details | D2: Notes | E2: Action Taken | F2: Contact (BuildCenter)
A3: 10.225.4.136 | B3: tss1vdev0104.tshhosting.com | C3: Shutdown?
A4: 10.55.129.7 | B4: c951jrx | C4: Responds to ping | D4: The IP assignment for the following address does not match what DNS or ServiceManager says (since 030113): | E4: Both look fine? | F4: Michael Tyrrell
A5: 163.231.83.1 | B5: adobo | C5: Decommissioned | D5: Unix? | E5: Recycled IP
A6: 10.52.128.60 | B6: C111PESCSDBB1 | C6: Does not respond to pings | D6: IP addresses maps to eg-tlrdc-a14.tlr.thomson.com BCS07041 | F6: Michael Tyrrell
A7: 10.52.128.61 | B7: C111XZZOFDBB1 | C7: Host not reachable | D7: No SM record. BCS07041 | F7: Michael Tyrrell
A8: 10.52.128.67 | B8: C574KEXOFDBB2 | C8: Host not reachable | D8: Two IP addresses BC07232 | F8: Michael Tyrrell
A9: 10.52.128.69 | B9: C613QFPCSDBB2 | C9: No DNS Record | D9: BC07232 | F9: Michael Tyrrell
A10: 10.52.133.66 | B10: C582MCK | C10: No DNS Record | D10: BC07232 | F10: Michael Tyrrell
A11: 10.52.133.68 | B11: C268CUC | C11: No DNS Record | D11: BC07232 | F11: Michael Tyrrell
A12: 10.204.32.129 | B12: c696xvjtftta.tlr.thomson.com | C12: Responds to Ping | D12: The IP assignment for the following address does not match what DNS or ServiceManager says (since 051313): | E12: Both look fine? | F12: Kathy Nguyen
A13: 10.204.64.100 | B13: c290fscegnd10.tlr.thomson.com | C13: Responds to Ping | D13: The IP assignment for the following address does not match what DNS or ServiceManager says (since 021113): | E13: Both look fine? | F13: Aftab Butt
A14: 10.204.64.114 | B14: c014mszgrdb2e | C14: Responds to ping | D14: IP address shows 10.205.67.25 | F14: Linda Huling
A15: 10.204.64.115 | B15: c329hbvgrdb2f | C15: Responds to ping | D15: IP address shows 10.205.67.26 | F15: Linda Huling
A16: 10.204.64.96 | B16: c221dyhegnd06.tlr.thomson.com | C16: Responds to Ping | D16: The IP assignment for the following address does not match what DNS or ServiceManager says (since 021213): | E16: Both look fine? | F16: Aftab Butt
A17: 10.204.64.97 | B17: c494hqvegnd07.tlr.thomson.com | C17: Responds to Ping | D17: The IP assignment for the following address does not match what DNS or ServiceManager says (since 021213): | E17: Both look fine? | F17: Aftab Butt
A18: 10.205.54.109 | B18: EG-SCMECOM-A04 | C18: Does not respond to pings | D18: IP address shows 10.221.69.54 | E18: Recycled | F18: Todd Burmaster
A19: 10.206.19.107 | B19: pvcluster.int.thomsonreuters.com | C19: Device Name shows C499WPR | D19: No SM record.
A20: 10.213.28.97 | B20: EG-SSCOPE-H22 | C20: Does not respond to pings | D20: IP address shows 167.68.64.3 | E20: Recycled
A21: 10.213.32.11 | B21: eg-sirappq-b04 | C21: Does not respond to ping (since 022113) | D21: IP now 163.231.98.1 (SM) | E21: Recycled IP
A22: 10.214.12.39 | B22: EG-DCEWEBQA-B01 | C22: Responds to Pings | D22: IP address shows 10.204.16.6 | F22: Linda Huling
A23: 10.215.31.40 | B23: c234qgj.ecom.tlrg.com | C23: Responds to pings | D23: The IP assignment for the following address does not match what DNS or ServiceManager says (since 032513): | F23: Joellen Depalma
A24: 10.216.64.10 | B24: EG-TAWEB-A05 | C24: Does not respond to ping (since 030413) | D24: V2V NEW IP 10.216.19.65 | E24: Recycled IP
A25: 10.216.64.3 | B25: EG-TAWEB-A04 | C25: Does not respond to ping (since 030213) | D25: IP now 10.216.19.64 (SM) | E25: Recycled IP
A26: 10.220.17.200 | B26: eg-j3rsqldv-b03 | C26: Decommissioned | E26: Recycled IP
A27: 10.220.20.141 | B27: EG-ELTVMDV-B12 | C27: Does not respond to ping (since 031213) | D27: CR0502751
A28: 10.220.20.142 | B28: EG-ELTVMDV-B13 | C28: Does not respond to ping (since 031213) | D28: CR0502751
A29: 10.220.20.143 | B29: eg-eltvmdv-b14 | C29: Does not respond to ping (since 031213) | D29: CR0502751
A30: 10.220.20.144 | B30: eg-eltvmdv-b15 | C30: Does not respond to ping (since 031213) | D30: CR0502751
A31: 10.220.48.3 | B31: RA-EG-WCTSQLQA-B02 | C31: Does not respond to ping (since 030213) | D31: IP now 10.220.42.28 (SM) | E31: Recycled IP
A32: 10.221.240.94 | B32: RA-EG-TFBSQL-B01 | C32: Decommissioned | E32: Recycled IP
A33: 10.221.249.129 | B33: RA-TLRUSMNEAGAPP06 | C33: No DNS Record | E33: Recycled IP
A34: 10.221.249.216 | B34: RA_TLRUSMNEAGAPP03 | C34: No DNS Record | E34: Recycled IP
A35: 10.221.253.147 | B35: TLRUSMNEAGAPP07 | C35: Decommissioned | E35: Recycled IP
A36: 10.221.254.152 | B36: EG-WEBAPP-A03 | C36: P2V Decommission | D36: Start June 6 | F36: Klarissa Mueller
A37: 10.221.254.195 | B37: EG-DASYNCQA-A06 | C37: Does not respond to ping (since 030613) | D37: Decommissioned | E37: Recycled IP
A38: 10.221.254.98 | B38: EG-DASYNC-A07 | C38: Does not respond to ping (since 030113) | D38: Decommissioned | E38: Recycled IP
A39: 10.221.64.115 | B39: EG-SWGADM-B01 | C39: Does not respond to ping (since 031013) | D39: P2V | E39: Recycled IP
A40: 10.221.68.4 | B40: EG-SWGADM-A02 | C40: Does not respond to ping (since 031113) | D40: P2V | E40: Recycled IP
...

Sheet Dustin
A1: IP Address | B1: Server Name | C1: IM/CR | D1: jorenby's notes | E1: Zipper Error | F1: Decommission - Brief Description | G1: Status | H1: IP Address in Service Manager | I1: Possible Name
A2: 10.51.5.129 | B2: c241ztuu2tmg1.erf.thomson.com | D2: Shutdown? Can't find OOB | E2: This IP's assignment information does not match DNS or ServiceManager (since 050313)
A3: 10.51.5.130 | B3: c671ppvu2tmg2.erf.thomson.com | D3: Shutdown? Can't find OOB | E3: This IP's assignment information does not match DNS or ServiceManager (since 050913)
A4: 10.52.130.98 | B4: C265EZJGRCSNP | D4: Shutdown? Can't find OOB | E4: Does not respond to ping (since 012913) | G4: DEPLOYED | H4: 10.52.145.1 | I4: C265EZJGRCSNP
A5: 10.52.134.51 | B5: C111UBRLHUB03 | D5: IP address shows 10.52.134.19 | E5: Does not respond to ping (since 012913) | G5: DEPLOYED | H5: 10.52.134.19 | I5: C111UBRLHUB03
A6: 10.52.142.57 | B6: C828QPKQFS02 | D6: IP address shows 10.52.184.15 | E6: Does not respond to ping (since 021213) | G6: BUILD COMPLETE | H6: 10.52.184.15 | I6: C828QPKQFS02
A7: 10.55.129.7 | B7: c951jrx.mgmt.tlrg.com | D7: The IP assignment for the following address does not match what DNS or ServiceManager says (since 030113): | E7: This IP's assignment information does not match DNS or ServiceManager (since 030113)
A8: 10.59.176.75 | B8: RA-C888UXQMPUB01 | C8: IM4454689 | D8: No SM record. | E8: Does not respond to ping (since 020513) | G8: BUILD COMPLETE | H8: 10.51.5.17 | I8: C888UXQMPUB01
A9: 10.204.32.129 | B9: c696xvjtftta.tlr.thomson.com | D9: The IP assignment for the following address does not match what DNS or ServiceManager says (since 051313): | E9: This IP's assignment information does not match DNS or ServiceManager (since 051313) | G9: BUILD COMPLETE | H9: 10.204.32.129 | I9: C696XVJTFTTA
A10: 10.204.64.96 | B10: c221dyhegnd06.tlr.thomson.com | D10: The IP assignment for the following address does not match what DNS or ServiceManager says (since 021213): | E10: This IP's assignment information does not match DNS or ServiceManager (since 021213) | G10: DEPLOYED | H10: 10.204.64.96 | I10: C221DYHEGND06
A11: 10.204.64.97 | B11: c494hqvegnd07.tlr.thomson.com | D11: The IP assignment for the following address does not match what DNS or ServiceManager says (since 021213): | E11: This IP's assignment information does not match DNS or ServiceManager (since 021213) | G11: DEPLOYED | H11: 10.204.64.97 | I11: C494HQVEGND07
A12: 10.204.64.100 | B12: c290fscegnd10.tlr.thomson.com | D12: The IP assignment for the following address does not match what DNS or ServiceManager says (since 021113): | E12: This IP's assignment information does not match DNS or ServiceManager (since 021113) | G12: DEPLOYED | H12: 10.204.64.100 | I12: C290FSCEGND10
A13: 10.204.64.114 | B13: c014mszgrdb2e | D13: IP address shows 10.205.67.25 | E13: Does not respond to ping (since 011113) | G13: DEPLOYED | H13: 10.205.67.25 | I13: C014MSZGRDB2E
A14: 10.204.64.115 | B14: c329hbvgrdb2f | D14: IP address shows 10.205.67.26 | E14: Does not respond to ping (since 011113) | G14: DEPLOYED | H14: 10.205.67.26 | I14: C329HBVGRDB2F
A15: 10.205.54.109 | B15: EG-SCMECOM-A04 | D15: IP address shows 10.221.69.54 | E15: Does not respond to ping (since 012413) | G15: DEPLOYED | H15: 10.221.69.54 | I15: EG-SCMECOM-A04
A16: 10.213.28.97 | B16: EG-SSCOPE-H22 | D16: IP address shows 167.68.64.3 | E16: Does not respond to ping (since 020713) | G16: DEPLOYED | H16: 167.68.64.3 | I16: eg-sscope-h22
A17: 10.214.12.39 | B17: EG-DCEWEBQA-B01 | D17: IP address shows 10.204.16.6 | E17: Does not respond to ping (since 021213) | G17: DEPLOYED | H17: 10.204.16.85 | I17: EG-DCEWEBQA-B01
A18: 10.215.31.40 | B18: c234qgj.ecom.tlrg.com | D18: The IP assignment for the following address does not match what DNS or ServiceManager says (since 032513): | E18: This IP's assignment information does not match DNS or ServiceManager (since 032513)
A19: 10.220.17.200 | B19: eg-j3rsqldv-b03 | D19: 0 | E19: Does not respond to ping (since 020413) | F19: CR0649162 - Decommission - BuildCenter: BCS10492 - EG-J3RSQLDV-B03 - Close Time:04/26/2013 08:50:36 | I19: 130426 - 1S88631SU99NV626 (EG-J3RSQLDV-B03)
A20: 10.221.240.94 | B20: RA-EG-TFBSQL-B01 | D20: No SM record. | E20: Does not respond to ping (since 020113) | F20: CR0619312 - Decommission - BuildCenter: BCS08950 - EG-TFBSQL-B01 - Close Time:02/12/2013 06:27:17 | I20: 130109 - Logical Image (eg-tfbsql-b01c)
A21: 10.221.253.147 | B21: TLRUSMNEAGAPP07 | D21: 0 | E21: Does not respond to ping (since 021413) | F21: CR0626151 - Decommission - BuildCenter: BCS10065 - TLRUSMNEAGAPP07 - Close Time:03/12/2013 04:23:03 | I21: 130312 - KPWNP68 (TLRUSMNEAGAPP07)
A22: 10.221.254.152 | B22: EG-WEBAPP-A03 | D22: Start June 6 | E22: Does not respond to ping (since 010913) | G22: DEPLOYED | H22: 10.220.68.173 | I22: eg-webapp-a03
A23: 10.225.4.136 | B23: tss1vdev0104.tshhosting.com | D23: 0 | E23: Does not respond to ping (since 120712)
A24: 10.226.45.37 | B24: tshielkcmgbld01-ilo | D24: No SM record. | E24: Does not respond to ping (since 111212)
A25: 10.236.191.147 | B25: TSHUSMNEAGVIR03-OOB | D25: No SM record. | E25: Does not respond to ping (since 010413) | F25: CR0608313 - Decommission - BuildCenter: BCS08456 - TSHUSMNEAGVIR03 - Close Time:01/22/2013 10:48:32 | I25: 130109 - M00BNCZ154 (TSHUSMNEAGVIR03)
A26: 163.231.16.2 | B26: tlrusmneagapp04 | D26: No SM record. | E26: Does not respond to ping (since 021513) | F26: CR0623754 - Decommission - BuildCenter: BCS10065 - TLRUSMNEAGAPP04 - Close Time:03/03/2013 17:59:14 | I26: 130304 - 78AY646 (tlrusmneagapp04)
A27: 163.231.22.167 | B27: tlrusmneagapp11 | D27: 0 | E27: Does not respond to ping (since 012613) | F27: CR0627914 - Decommission - BuildCenter: BCS10065 - TLRUSMNEAGAPP11 - Close Time:03/13/2013 07:21:06 | I27: 130313 - 23A7363 (TLRUSMNEAGAPP11)
A28: 163.231.29.167 | B28: eagh-erfpisa03 | D28: 0 | E28: Does not respond to ping (since 120412) | G28: DEPLOYED | H28: 163.231.29.129 | I28: EAGH-ERFPISA03
A29: 163.231.82.150 | B29: EG-TFBSQL-B01C | D29: 0 | E29: Does not respond to ping (since 021413) | F29: CR0608554 - Decommission - BuildCenter: BCS08950 - eg-tfbsql-b01c - Close Time:01/09/2013 06:02:18 | I29: 130109 - Logical Image (eg-tfbsql-b01c)
A30: 163.231.82.151 | B30: EG-TFBSQL-B01R | D30: 0 | E30: Does not respond to ping (since 021413) | F30: CR0608553 - Decommission - BuildCenter: BCS08950 - eg-tfbsql-b01r - Close Time:01/09/2013 06:03:25 | I30: 130109 - Logical Image (eg-tfbsql-b01r)
A31: 163.231.82.152 | B31: EG-TFBSQL-B01M | D31: 0 | E31: Does not respond to ping (since 021413) | F31: CR0608555 - Decommission - BuildCenter: BCS08950 - eg-tfbsql-b01m - Close Time:01/09/2013 06:00:11 | I31: 130109 - Logical Image (eg-tfbsql-b01m)
A32: 163.231.83.1 | B32: adobo.tfn.com | D32: 0 | E32: Does not respond to ping (since 011213) | I32: 100104 - 1061D2F (ADOBO)
A33: 163.231.83.217 | B33: pfsso.int.thomsonreuters.com | D33: 0 | E33: Does not respond to ping (since 011213)
A34: 163.231.99.40 | B34: koro | D34: DNS record | E34: Does not respond to ping (since 020413) | G34: DEPLOYED | H34: 163.231.99.199 | I34: koro
A35: 10.51.0.21 | B35: pvdr.int.thomsonreuters.com | D35: Listed SM Hostname - C671RBM | E35: This IP's assignment information does not match DNS or ServiceManager (since 050713)
A36: 10.51.5.9 | B36: C888UXQU2PUB1 | D36: Second IP address 10.59.176.31 | E36: Does not respond to ping (since 012913)
A37: 10.51.5.10 | B37: C824XWEU2PUB3 | D37: January 29th 2013 - Last ping | E37: Does not respond to ping (since 012913)
A38: 10.52.128.60 | B38: C111PESCSDBB1 | D38: IP addresses maps to eg-tlrdc-a14.tlr.thomson.com | E38: Does not respond to ping (since 012913) | G38: BUILD COMPLETE | I38: C111PESCSDBB1
A39: 10.52.128.61 | B39: C111XZZOFDBB1 | D39: No SM record. | E39: Does not respond to ping (since 012913) | G39: BUILD COMPLETE | I39: C111XZZOFDBB1
A40: 10.52.128.67 | B40: C574KEXOFDBB2 | D40: Two IP addresses | E40: Does not respond to ping (since 012913) | G40: BUILD COMPLETE | I40: C574KEXOFDBB2
...

Sheet Zipper 6-13
A1: IPAddress | B1: Hostname | C1: Description | D1: Compared | E1: Notes | F1: Action Taken
A2: 10.204.32.129 | B2: c696xvjtftta | C2: This IP's assignment information does not match DNS or ServiceManager (since 051313) | D2: =VLOOKUP(A2,Chris!A:F,1,0) -> 10.204.32.129
A3: 10.204.64.100 | B3: c290fscegnd10 | C3: This IP's assignment information does not match DNS or ServiceManager (since 021113) | D3: =VLOOKUP(A3,Chris!A:F,1,0) -> 10.204.64.100
A4: 10.204.64.114 | B4: c014mszgrdb2e | C4: Does not respond to ping (since 011113) | D4: =VLOOKUP(A4,Chris!A:F,1,0) -> 10.204.64.114
A5: 10.204.64.115 | B5: c329hbvgrdb2f | C5: Does not respond to ping (since 011113) | D5: =VLOOKUP(A5,Chris!A:F,1,0) -> 10.204.64.115
A6: 10.204.64.96 | B6: c221dyhegnd06 | C6: This IP's assignment information does not match DNS or ServiceManager (since 021213) | D6: =VLOOKUP(A6,Chris!A:F,1,0) -> 10.204.64.96
A7: 10.204.64.97 | B7: c494hqvegnd07 | C7: This IP's assignment information does not match DNS or ServiceManager (since 021213) | D7: =VLOOKUP(A7,Chris!A:F,1,0) -> 10.204.64.97
A8: 10.206.19.107 | B8: pvcluster | C8: This IP's assignment information does not match DNS or ServiceManager (since 050713) | D8: =VLOOKUP(A8,Chris!A:F,1,0) -> 10.206.19.107
A9: 10.213.32.11 | B9: eg-sirappq-b04 | C9: Does not respond to ping (since 022113) | D9: =VLOOKUP(A9,Chris!A:F,1,0) -> 10.213.32.11 | E9: IP now 163.231.98.1 (SM) | F9: Recycled IP
A10: 10.215.31.40 | B10: c234qgj | C10: This IP's assignment information does not match DNS or ServiceManager (since 032513) | D10: =VLOOKUP(A10,Chris!A:F,1,0) -> 10.215.31.40
A11: 10.216.64.3 | B11: EG-TAWEB-A04 | C11: Does not respond to ping (since 030213) | D11: =VLOOKUP(A11,Chris!A:F,1,0) -> 10.216.64.3 | E11: IP now 10.216.19.64 (SM) | F11: Recycled IP
A12: 10.220.48.3 | B12: RA-EG-WCTSQLQA-B02 | C12: Does not respond to ping (since 030213) | D12: =VLOOKUP(A12,Chris!A:F,1,0) -> 10.220.48.3 | E12: IP now 10.220.42.28 (SM) | F12: Recycled IP
A13: 10.221.254.98 | B13: EG-DASYNC-A07 | C13: Does not respond to ping (since 030113) | D13: =VLOOKUP(A13,Chris!A:F,1,0) -> 10.221.254.98 | E13: Decommissioned | F13: Recycled IP
A14: 10.221.68.45 | B14: EG-TAWEB-A06 | C14: Does not respond to ping (since 030213) | D14: =VLOOKUP(A14,Chris!A:F,1,0) -> 10.221.68.45 | E14: IP now 10.215.34.201 (SM) | F14: Recycled IP
A15: 10.225.4.136 | B15: tss1vdev0104 | C15: Does not respond to ping (since 120712) | D15: =VLOOKUP(A15,Chris!A:F,1,0) -> 10.225.4.136
A16: 10.226.45.37 | B16: tshielkcmgbld01-ilo | C16: Does not respond to ping (since 111212) | D16: =VLOOKUP(A16,Chris!A:F,1,0) -> 10.226.45.37
A17: 10.226.9.144 | B17: C948DAQ | C17: This IP's assignment information does not match DNS or ServiceManager (since 060613) | D17: =VLOOKUP(A17,Chris!A:F,1,0) -> 10.226.9.144 | E17: Contact Amanda mayers (BC) | F17: BCS11407
A18: 10.226.9.89 | B18: c400sccicapln | C18: This IP's assignment information does not match DNS or ServiceManager (since 060413) | D18: =VLOOKUP(A18,Chris!A:F,1,0) -> 10.226.9.89 | E18: CR0665011 | F18: Ongoing CR. Waiting to Recycle
A19: 10.226.9.90 | B19: C111JEMICAPLN | C19: This IP is apparently in use, but it has not been assigned (since 060413) | D19: =VLOOKUP(A19,Chris!A:F,1,0) -> 10.226.9.90 | E19: Decommissioned | F19: Ongoing CR. Waiting to Recycle | G19: SM Shows C066FDTICAPLN
A20: 10.51.0.21 | B20: pvdr | C20: This IP's assignment information does not match DNS or ServiceManager (since 050713) | D20: =VLOOKUP(A20,Chris!A:F,1,0) -> 10.51.0.21
A21: 10.51.5.129 | B21: c241ztuu2tmg1 | C21: This IP's assignment information does not match DNS or ServiceManager (since 050313) | D21: =VLOOKUP(A21,Chris!A:F,1,0) -> 10.51.5.129
A22: 10.51.5.130 | B22: c671ppvu2tmg2 | C22: This IP's assignment information does not match DNS or ServiceManager (since 050913) | D22: =VLOOKUP(A22,Chris!A:F,1,0) -> 10.51.5.130
A23: 10.52.128.60 | B23: C111PESCSDBB1 | C23: Does not respond to ping (since 012913) | D23: =VLOOKUP(A23,Chris!A:F,1,0) -> 10.52.128.60
A24: 10.52.128.61 | B24: C111XZZOFDBB1 | C24: Does not respond to ping (since 012913) | D24: =VLOOKUP(A24,Chris!A:F,1,0) -> 10.52.128.61
A25: 10.52.128.67 | B25: C574KEXOFDBB2 | C25: Does not respond to ping (since 012913) | D25: =VLOOKUP(A25,Chris!A:F,1,0) -> 10.52.128.67
A26: 10.52.128.69 | B26: C613QFPCSDBB2 | C26: Does not respond to ping (since 012913) | D26: =VLOOKUP(A26,Chris!A:F,1,0) -> 10.52.128.69
A27: 10.52.130.98 | B27: C265EZJGRCSNP | C27: Does not respond to ping (since 012913) | D27: =VLOOKUP(A27,Chris!A:F,1,0) -> 10.52.130.98
A28: 10.52.133.58 | B28: c237mkh | C28: Does not respond to ping (since 012913) | D28: =VLOOKUP(A28,Chris!A:F,1,0) -> 10.52.133.58
A29: 10.52.133.59 | B29: c946wpw | C29: Does not respond to ping (since 012913) | D29: =VLOOKUP(A29,Chris!A:F,1,0) -> 10.52.133.59
A30: 10.52.133.60 | B30: c451utq | C30: Does not respond to ping (since 012913) | D30: =VLOOKUP(A30,Chris!A:F,1,0) -> 10.52.133.60
A31: 10.52.133.61 | B31: c662yxu | C31: Does not respond to ping (since 012913) | D31: =VLOOKUP(A31,Chris!A:F,1,0) -> 10.52.133.61
... A43: 192.168.250.131 | B43: aujpjptokdaiwcp-a01 | C43: This IP's assignment information does not match DNS or ServiceManager (since 113012) | D43: =VLOOKUP(A43,Chris!A:F,1,0) -> 192.168.250.131

Sheet Zipper 6-18
A1: IPAddress | B1: Hostname | C1: Description | D1: Compared | E1: Second Compare | F1: Notes | G1: Action Taken
A2: 192.168.250.129 | B2: tok1-dist1.tfn.com | C2: This IP's assignment information does not match DNS or ServiceManager (since 113012) | D2: =VLOOKUP(A2,Chris!A:F,2,0) -> tok1-dist1.tfn.com | E2: =VLOOKUP(A2,'Zipper 6-13'!A2:F43,2,0) -> tok1-dist1
A3: 192.168.250.131 | B3: aujpjptokdaiwcp-a01.tfn.com | C3: This IP's assignment information does not match DNS or ServiceManager (since 113012) | D3: =VLOOKUP(A3,Chris!A:F,2,0) -> aujpjptokdaiwcp-a01.tfn.com | E3: =VLOOKUP(A3,'Zipper 6-13'!A3:F44,2,0) -> aujpjptokdaiwcp-a01
A4: 10.51.0.21 | B4: pvdr.int.thomsonreuters.com | C4: This IP's assignment information does not match DNS or ServiceManager (since 050713) | D4: =VLOOKUP(A4,Chris!A:F,2,0) -> pvdr.int.thomsonreuters.com | E4: =VLOOKUP(A4,'Zipper 6-13'!A4:F45,2,0) -> pvdr
A5: 10.52.128.60 | B5: C111PESCSDBB1 | C5: Does not respond to ping (since 012913) | D5: =VLOOKUP(A5,Chris!A:F,2,0) -> C111PESCSDBB1 | E5: =VLOOKUP(A5,'Zipper 6-13'!A5:F46,2,0) -> C111PESCSDBB1
A6: 10.52.128.61 | B6: C111XZZOFDBB1 | C6: Does not respond to ping (since 012913) | D6: =VLOOKUP(A6,Chris!A:F,2,0) -> C111XZZOFDBB1 | E6: =VLOOKUP(A6,'Zipper 6-13'!A6:F47,2,0) -> C111XZZOFDBB1
A7: 10.52.128.67 | B7: C574KEXOFDBB2 | C7: Does not respond to ping (since 012913) | D7: =VLOOKUP(A7,Chris!A:F,2,0) -> C574KEXOFDBB2 | E7: =VLOOKUP(A7,'Zipper 6-13'!A7:F48,2,0) -> C574KEXOFDBB2
A8: 10.52.128.69 | B8: C613QFPCSDBB2 | C8: Does not respond to ping (since 012913) | D8: =VLOOKUP(A8,Chris!A:F,2,0) -> C613QFPCSDBB2 | E8: =VLOOKUP(A8,'Zipper 6-13'!A8:F49,2,0) -> C613QFPCSDBB2
A9: 10.52.133.58 | B9: c237mkh | C9: Does not respond to ping (since 012913) | D9: =VLOOKUP(A9,Chris!A:F,2,0) -> c237mkh | E9: =VLOOKUP(A9,'Zipper 6-13'!A9:F50,2,0) -> c237mkh
A10: 10.52.133.59 | B10: c946wpw | C10: Does not respond to ping (since 012913) | D10: =VLOOKUP(A10,Chris!A:F,2,0) -> c946wpw | E10: =VLOOKUP(A10,'Zipper 6-13'!A10:F51,2,0) -> c946wpw
A11: 10.52.133.60 | B11: c451utq | C11: Does not respond to ping (since 012913) | D11: =VLOOKUP(A11,Chris!A:F,2,0) -> c451utq | E11: =VLOOKUP(A11,'Zipper 6-13'!A11:F52,2,0) -> c451utq
A12: 10.52.133.61 | B12: c662yxu | C12: Does not respond to ping (since 012913) | D12: =VLOOKUP(A12,Chris!A:F,2,0) -> c662yxu | E12: =VLOOKUP(A12,'Zipper 6-13'!A12:F53,2,0) -> c662yxu
A13: 10.52.133.66 | B13: C582MCK | C13: Does not respond to ping (since 012913) | D13: =VLOOKUP(A13,Chris!A:F,2,0) -> C582MCK | E13: =VLOOKUP(A13,'Zipper 6-13'!A13:F54,2,0) -> C582MCK
... A23: 10.59.176.75 | B23: RA-C888UXQMPUB01 | C23: Does not respond to ping (since 020513) | D23: =VLOOKUP(A23,Chris!A:F,2,0) -> RA-C888UXQMPUB01 | E23: =VLOOKUP(A23,'Zipper 6-13'!A23:F64,2,0) -> RA-C888UXQMPUB01
A24: 10.216.64.10 | B24: EG-TAWEB-A05 | C24: Does not respond to ping (since 030413) | D24: =VLOOKUP(A24,Chris!A:F,2,0) -> EG-TAWEB-A05 | E24: =VLOOKUP(A24,'Zipper 6-13'!A24:F65,2,0) -> #N/A | F24: V2V NEW IP 10.216.19.65 | G24: Recycled IP
A25: 10.221.68.45 | B25: EG-TAWEB-A06 | C25: Does not respond to ping (since 030213) | D25: =VLOOKUP(A25,Chris!A:F,2,0) -> EG-TAWEB-A06 | E25: =VLOOKUP(A25,'Zipper 6-13'!A25:F66,2,0) -> #N/A | F25: NEW IP 10.215.34.201 | G25: Recycled IP
A26: 10.221.68.49 | B26: EG-TASQL-A04 | C26: Does not respond to ping (since 030413) | D26: =VLOOKUP(A26,Chris!A:F,2,0) -> EG-TASQL-A04 | E26: =VLOOKUP(A26,'Zipper 6-13'!A26:F67,2,0) -> #N/A | F26: NEW IP 10.215.34.202 | G26: Recycled IP
A27: 10.221.254.195 | B27: EG-DASYNCQA-A06 | C27: Does not respond to ping (since 030613) | D27: =VLOOKUP(A27,Chris!A:F,2,0) -> EG-DASYNCQA-A06 | E27: =VLOOKUP(A27,'Zipper 6-13'!A27:F68,2,0) -> #N/A | F27: Decommissioned | G27: Recycled IP
A28: 10.226.9.89 | B28: c400sccicapln.tlr.thomson.com | C28: This IP's assignment information does not match DNS or ServiceManager (since 060413) | D28: =VLOOKUP(A28,Chris!A:F,2,0) -> c400sccicapln | E28: =VLOOKUP(A28,'Zipper 6-13'!A28:F69,2,0) -> #N/A | F28: BCS11407
A29: 10.226.9.90 | B29: C066FDTICAPLN (SM) | C29: This IP is apparently in use, but it has not been assigned (since 061113) | D29: =VLOOKUP(A29,Chris!A:F,2,0) -> C111JEMICAPLN | E29: =VLOOKUP(A29,'Zipper 6-13'!A29:F70,2,0) -> #N/A
A30: 10.226.9.144 | B30: C948DAO | C30: This IP's assignment information does not match DNS or ServiceManager (since 061113) | D30: =VLOOKUP(A30,Chris!A:F,2,0) -> C948DAQ | E30: =VLOOKUP(A30,'Zipper 6-13'!A30:F71,2,0) -> #N/A | F30: BCS11407
A31: 163.231.94.89 | B31: eg-hdsadm-a04.int.westgroup.com | C31: Does not respond to ping (since 030313) | D31: =VLOOKUP(A31,Chris!A:F,2,0) -> eg-hdsadm-a04.int.westgroup.com | E31: =VLOOKUP(A31,'Zipper 6-13'!A31:F72,2,0) -> #N/A | F31: ???

Sheet Zipper 6-25
A1: IPAddress | B1: Hostname | C1: Description | D1: Compared | E1: Notes | F1: Action Taken
A2: 10.51.0.21 | B2: pvdr.int.thomsonreuters.com | C2: This IP's assignment information does not match DNS or ServiceManager (since 050713) | D2: =VLOOKUP(A2,Chris!A:F,1,0) -> 10.51.0.21
A3: 10.52.128.60 | B3: C111PESCSDBB1 | C3: Does not respond to ping (since 012913) | D3: =VLOOKUP(A3,Chris!A:F,1,0) -> 10.52.128.60
A4: 10.52.128.61 | B4: C111XZZOFDBB1 | C4: Does not respond to ping (since 012913) | D4: =VLOOKUP(A4,Chris!A:F,1,0) -> 10.52.128.61
A5: 10.52.128.67 | B5: C574KEXOFDBB2 | C5: Does not respond to ping (since 012913) | D5: =VLOOKUP(A5,Chris!A:F,1,0) -> 10.52.128.67
A6: 10.52.128.69 | B6: C613QFPCSDBB2 | C6: Does not respond to ping (since 012913) | D6: =VLOOKUP(A6,Chris!A:F,1,0) -> 10.52.128.69
A7: 10.52.133.58 | B7: c237mkh | C7: Does not respond to ping (since 012913) | D7: =VLOOKUP(A7,Chris!A:F,1,0) -> 10.52.133.58
A8: 10.52.133.59 | B8: c946wpw | C8: Does not respond to ping (since 012913) | D8: =VLOOKUP(A8,Chris!A:F,1,0) -> 10.52.133.59
A9: 10.52.133.60 | B9: c451utq | C9: Does not respond to ping (since 012913) | D9: =VLOOKUP(A9,Chris!A:F,1,0) -> 10.52.133.60
A10: 10.52.133.61 | B10: c662yxu | C10: Does not respond to ping (since 012913) | D10: =VLOOKUP(A10,Chris!A:F,1,0) -> 10.52.133.61
A11: 10.52.133.66 | B11: C582MCK | C11: Does not respond to ping (since 012913) | D11: =VLOOKUP(A11,Chris!A:F,1,0) -> 10.52.133.66
A12: 10.52.133.67 | B12: C574KEXOFDBB2 | C12: Does not respond to ping (since 012913) | D12: =VLOOKUP(A12,Chris!A:F,1,0) -> #N/A
A13: 10.52.133.68 | B13: C268CUC | C13: Does not respond to ping (since 012913) | D13: =VLOOKUP(A13,Chris!A:F,1,0) -> 10.52.133.68
... A15: 10.206.19.107 | B15: pvcluster.int.thomsonreuters.com | C15: This IP's assignment information does not match DNS or ServiceManager (since 050713) | D15: =VLOOKUP(A15,Chris!A:F,1,0) -> 10.206.19.107
A16: 10.220.20.141 | B16: EG-ELTVMDV-B12 | C16: Does not respond to ping (since 031213) | D16: =VLOOKUP(A16,Chris!A:F,1,0) -> 10.220.20.141 | E16: CR0502751 | F16: Recycled IP
A17: 10.220.20.142 | B17: EG-ELTVMDV-B13 | C17: Does not respond to ping (since 031213) | D17: =VLOOKUP(A17,Chris!A:F,1,0) -> 10.220.20.142 | E17: CR0502751 | F17: Recycled IP
A18: 10.220.20.143 | B18: eg-eltvmdv-b14 | C18: Does not respond to ping (since 031213) | D18: =VLOOKUP(A18,Chris!A:F,1,0) -> 10.220.20.143 | E18: CR0502751 | F18: Recycled IP
A19: 10.220.20.144 | B19: eg-eltvmdv-b15 | C19: Does not respond to ping (since 031213) | D19: =VLOOKUP(A19,Chris!A:F,1,0) -> 10.220.20.144 | E19: CR0502751 | F19: Recycled IP
A20: 10.51.5.129 | B20: c241ztuu2tmg1.erf.thomson.com | C20: This IP's assignment information does not match DNS or ServiceManager (since 050313) | D20: =VLOOKUP(A20,Chris!A:F,1,0) -> 10.51.5.129
A21: 10.51.5.130 | B21: c671ppvu2tmg2.erf.thomson.com | C21: This IP's assignment information does not match DNS or ServiceManager (since 050913) | D21: =VLOOKUP(A21,Chris!A:F,1,0) -> 10.51.5.130
A22: 10.52.130.98 | B22: C265EZJGRCSNP | C22: Does not respond to ping (since 012913) | D22: =VLOOKUP(A22,Chris!A:F,1,0) -> 10.52.130.98
A23: 10.52.134.51 | B23: C111UBRLHUB03 | C23: Does not respond to ping (since 012913) | D23: =VLOOKUP(A23,Chris!A:F,1,0) -> 10.52.134.51
A24: 10.52.142.57 | B24: C828QPKQFS02 | C24: Does not respond to ping (since 021213) | D24: =VLOOKUP(A24,Chris!A:F,1,0) -> 10.52.142.57
A25: 10.55.129.7 | B25: c951jrx.mgmt.tlrg.com | C25: This IP's assignment information does not match DNS or ServiceManager (since 030113) | D25: =VLOOKUP(A25,Chris!A:F,1,0) -> 10.55.129.7
A26: 10.59.176.75 | B26: RA-C888UXQMPUB01 | C26: Does not respond to ping (since 020513) | D26: =VLOOKUP(A26,Chris!A:F,1,0) -> 10.59.176.75
A27: 10.204.32.129 | B27: c696xvjtftta.tlr.thomson.com | C27: This IP's assignment information does not match DNS or ServiceManager (since 051313) | D27: =VLOOKUP(A27,Chris!A:F,1,0) -> 10.204.32.129
A28: 10.204.64.96 | B28: c221dyhegnd06.tlr.thomson.com | C28: This IP's assignment information does not match DNS or ServiceManager (since 021213) | D28: =VLOOKUP(A28,Chris!A:F,1,0) -> 10.204.64.96
A29: 10.204.64.97 | B29: c494hqvegnd07.tlr.thomson.com | C29: This IP's assignment information does not match DNS or ServiceManager (since 021213) | D29: =VLOOKUP(A29,Chris!A:F,1,0) -> 10.204.64.97
A30: 10.204.64.100 | B30: c290fscegnd10.tlr.thomson.com | C30: This IP's assignment information does not match DNS or ServiceManager (since 021113) | D30: =VLOOKUP(A30,Chris!A:F,1,0) -> 10.204.64.100
A31: 10.204.64.114 | B31: c014mszgrdb2e | C31: Does not respond to ping (since 011113) | D31: =VLOOKUP(A31,Chris!A:F,1,0) -> 10.204.64.114
... A33: 10.215.31.40 | B33: c234qgj.ecom.tlrg.com | C33: This IP's assignment information does not match DNS or ServiceManager (since 032513) | D33: =VLOOKUP(A33,Chris!A:F,1,0) -> 10.215.31.40
A34: 10.221.64.115 | B34: EG-SWGADM-B01 | C34: Does not respond to ping (since 031013) | D34: =VLOOKUP(A34,Chris!A:F,1,0) -> 10.221.64.115 | E34: P2V | F34: Recycled IP
A35: 10.221.68.4 | B35: EG-SWGADM-A02 | C35: Does not respond to ping (since 031113) | D35: =VLOOKUP(A35,Chris!A:F,1,0) -> 10.221.68.4 | E35: P2V | F35: Recycled IP
A36: 10.225.4.136 | B36: tss1vdev0104.tshhosting.com | C36: Does not respond to ping (since 120712) | D36: =VLOOKUP(A36,Chris!A:F,1,0) -> 10.225.4.136
A37: 10.226.50.195 | B37: C837PNSBLWEB | C37: Does not respond to ping (since 031513) | D37: =VLOOKUP(A37,Chris!A:F,1,0) -> 10.226.50.195 | E37: VLAN Change | F37: Recycled IP
A38: 163.231.83.217 | B38: pfsso.int.thomsonreuters.com | C38: Does not respond to ping (since 011213) | D38: =VLOOKUP(A38,Chris!A:F,1,0) -> 163.231.83.217
A39: 163.231.94.89 | B39: eg-hdsadm-a04.int.westgroup.com | C39: Does not respond to ping (since 030313) | D39: =VLOOKUP(A39,Chris!A:F,1,0) -> 163.231.94.89
A40: 163.231.99.40 | B40: koro | C40: Does not respond to ping (since 020413) | D40: =VLOOKUP(A40,Chris!A:F,1,0) -> 163.231.99.40
A41: 192.168.250.129 | B41: tok1-dist1.tfn.com | C41: This IP's assignment information does not match DNS or ServiceManager (since 113012) | D41: =VLOOKUP(A41,Chris!A:F,1,0) -> 192.168.250.129
A42: 192.168.250.131 | B42: aujpjptokdaiwcp-a01.tfn.com | C42: This IP's assignment information does not match DNS or ServiceManager (since 113012) | D42: =VLOOKUP(A42,Chris!A:F,1,0) -> 192.168.250.131

Sheet Zipper 7-2
A1: IPAddress | B1: Hostname | C1: Description | D1: Compared | E1: Notes | F1: Action Taken
A2: 192.168.250.129 | B2: tok1-dist1.tfn.com | C2: This IP's assignment information does not match DNS or ServiceManager (since 113012) | D2: =VLOOKUP(A2,Chris!A3:A80,1,0) -> 192.168.250.129
A3: 192.168.250.131 | B3: aujpjptokdaiwcp-a01.tfn.com | C3: This IP's assignment information does not match DNS or ServiceManager (since 113012) | D3: =VLOOKUP(A3,Chris!A4:A80,1,0) -> 192.168.250.131
A4: 10.51.0.21 | B4: pvdr.int.thomsonreuters.com | C4: This IP's assignment information does not match DNS or ServiceManager (since 050713) | D4: =VLOOKUP(A4,Chris!A5:A81,1,0) -> 10.51.0.21
A5: 10.52.128.60 | B5: C111PESCSDBB1 | C5: Does not respond to ping (since 012913) | D5: =VLOOKUP(A5,Chris!A6:A82,1,0) -> 10.52.128.60
A6: 10.52.128.61 | B6: C111XZZOFDBB1 | C6: Does not respond to ping (since 012913) | D6: =VLOOKUP(A6,Chris!A7:A83,1,0) -> 10.52.128.61
A7: 10.52.128.67 | B7: C574KEXOFDBB2 | C7: Does not respond to ping (since 012913) | D7: =VLOOKUP(A7,Chris!A8:A84,1,0) -> 10.52.128.67
A8: 10.52.128.69 | B8: C613QFPCSDBB2 | C8: Does not respond to ping (since 012913) | D8: =VLOOKUP(A8,Chris!A9:A85,1,0) -> 10.52.128.69
A9: 10.52.133.58 | B9: c237mkh | C9: Does not respond to ping (since 012913) | D9: =VLOOKUP(A9,Chris!A10:A86,1,0) -> 10.52.133.58
A10: 10.52.133.59 | B10: c946wpw | C10: Does not respond to ping (since 012913) | D10: =VLOOKUP(A10,Chris!A11:A87,1,0) -> 10.52.133.59
A11: 10.52.133.60 | B11: c451utq | C11: Does not respond to ping (since 012913) | D11: =VLOOKUP(A11,Chris!A12:A88,1,0) -> 10.52.133.60
A12: 10.52.133.61 | B12: c662yxu | C12: Does not respond to ping (since 012913) | D12: =VLOOKUP(A12,Chris!A13:A89,1,0) -> 10.52.133.61
A13: 10.52.133.66 | B13: C582MCK | C13: Does not respond to ping (since 012913) | D13: =VLOOKUP(A13,Chris!A14:A90,1,0) -> #N/A
A14: 10.52.133.67 | B14: C574KEXOFDBB2 | C14: Does not respond to ping (since 012913) | D14: =VLOOKUP(A14,Chris!A15:A91,1,0) -> #N/A
... A16: 10.52.133.69 | B16: C613QFPCSDBB2 | C16: Does not respond to ping (since 012913) | D16: =VLOOKUP(A16,Chris!A17:A93,1,0) -> #N/A
A17: 10.206.19.107 | B17: pvcluster | C17: This IP's assignment information does not match DNS or ServiceManager (since 050713) | D17: =VLOOKUP(A17,Chris!A18:A94,1,0) -> 10.206.19.107 | F17: DNS Changed SM
A18: 10.220.20.141 | B18: EG-ELTVMDV-B12 | C18: Does not respond to ping (since 031213) | D18: =VLOOKUP(A18,Chris!A19:A95,1,0) -> 10.220.20.141 | F18: Recycled IP
A19: 10.220.20.142 | B19: EG-ELTVMDV-B13 | C19: Does not respond to ping (since 031213) | D19: =VLOOKUP(A19,Chris!A20:A96,1,0) -> 10.220.20.142 | F19: Recycled IP
A20: 10.220.20.143 | B20: eg-eltvmdv-b14 | C20: Does not respond to ping (since 031213) | D20: =VLOOKUP(A20,Chris!A21:A97,1,0) -> 10.220.20.143 | F20: Recycled IP
A21: 10.220.20.144 | B21: eg-eltvmdv-b15 | C21: Does not respond to ping (since 031213) | D21: =VLOOKUP(A21,Chris!A22:A98,1,0) -> 10.220.20.144 | F21: Recycled IP
A22: 10.220.24.231 | B22: EG-TFSSQLD-B01 | C22: Does not respond to ping (since 031913) | D22: =VLOOKUP(A22,Chris!A23:A99,1,0) -> #N/A | E22: Retired | F22: Recycled IP
A23: 10.220.94.42 | B23: EG-TFSSQL-A02 | C23: Does not respond to ping (since 031913) | D23: =VLOOKUP(A23,Chris!A24:A100,1,0) -> #N/A | E23: Retired | F23: Recycled IP
A24: 167.68.238.194 | B24: eg-carstwb-a03 | C24: Does not respond to ping (since 031913) | D24: =VLOOKUP(A24,Chris!A25:A101,1,0) -> #N/A | E24: Retired | F24: Recycled IP
A25: 167.68.238.195 | B25: eg-carstwb-a03 | C25: Does not respond to ping (since 031913) | D25: =VLOOKUP(A25,Chris!A26:A102,1,0) -> #N/A | E25: Retired | F25: Recycled IP
A26: 10.51.2.74 | B26: c711tmecmgs01 | C26: Does not respond to ping (since 032113) | D26: =VLOOKUP(A26,Chris!A27:A103,1,0) -> #N/A | E26: BCS09360 | F26: IP Online
A27: 10.52.130.98 | B27: C265EZJGRCSNP | C27: Does not respond to ping (since 012913) | D27: =VLOOKUP(A27,Chris!A28:A104,1,0) -> 10.52.130.98
A28: 10.52.134.51 | B28: C111UBRLHUB03 | C28: Does not respond to ping (since 012913) | D28: =VLOOKUP(A28,Chris!A29:A105,1,0) -> 10.52.134.51
A29: 10.52.142.43 | B29: c720bvwcmgs01 | C29: Does not respond to ping (since 032113) | D29: =VLOOKUP(A29,Chris!A30:A106,1,0) -> #N/A | E29: BCS09309 | F29: IP Online
A30: 10.52.142.57 | B30: C828QPKQFS02 | C30: Does not respond to ping (since 021213) | D30: =VLOOKUP(A30,Chris!A31:A107,1,0) -> 10.52.142.57
A31: 10.55.129.7 | B31: c951jrx.mgmt.tlrg.com | C31: This IP's assignment information does not match DNS or ServiceManager (since 030113) | D31: =VLOOKUP(A31,Chris!A32:A108,1,0) -> #N/A
A32: 10.59.176.75 | B32: RA-C888UXQMPUB01 | C32: Does not respond to ping (since 020513) | D32: =VLOOKUP(A32,Chris!A33:A109,1,0) -> 10.59.176.75
A33: 10.204.32.129 | B33: c696xvjtftta | C33: This IP's assignment information does not match DNS or ServiceManager (since 051313) | D33: =VLOOKUP(A33,Chris!A34:A110,1,0) -> #N/A | F33: Update DNS (SM)
A34: 10.204.64.96 | B34: c221dyhegnd06 | C34: This IP's assignment information does not match DNS or ServiceManager (since 021213) | D34: =VLOOKUP(A34,Chris!A35:A111,1,0) -> #N/A | F34: Update DNS (SM)
A35: 10.204.64.97 | B35: c494hqvegnd07 | C35: This IP's assignment information does not match DNS or ServiceManager (since 021213) | D35: =VLOOKUP(A35,Chris!A36:A112,1,0) -> #N/A | F35: Update DNS (SM)
A36: 10.204.64.100 | B36: c290fscegnd10 | C36: This IP's assignment information does not match DNS or ServiceManager (since 021113) | D36: =VLOOKUP(A36,Chris!A37:A113,1,0) -> #N/A | F36: Update DNS (SM)
A37: 10.204.64.114 | B37: c014mszgrdb2e | C37: Does not respond to ping (since 011113) | D37: =VLOOKUP(A37,Chris!A38:A114,1,0) -> #N/A | E37: Moved | F37: Recycled IP
A38: 10.204.64.115 | B38: c329hbvgrdb2f | C38: Does not respond to ping (since 011113) | D38: =VLOOKUP(A38,Chris!A39:A115,1,0) -> #N/A | E38: Moved | F38: Recycled IP
A39: 10.205.69.10 | B39: boardlinkdav-dev | C39: This IP's assignment information does not match DNS or ServiceManager (since 062713) | D39: =VLOOKUP(A39,Chris!A40:A116,1,0) -> #N/A | E39: No SM | F39: IP Online
A40: 10.206.16.214 | B40: cubiscan-test | C40: This IP's assignment information does not match DNS or ServiceManager (since 070113) | D40: =VLOOKUP(A40,Chris!A41:A117,1,0) -> #N/A | E40: No SM | F40: IP Online
A41: 10.215.31.40 | B41: c234qgj | C41: This IP's assignment information does not match DNS or ServiceManager (since 032513) | D41: =VLOOKUP(A41,Chris!A42:A118,1,0) -> #N/A | F41: Update DNS (SM)
...

Sheet Zipper 7-9
A1: IPAddress | B1: Hostname | C1: Description | D1: Compared | E1: Notes | F1: Action Taken
A2: 10.213.24.223 | B2: ra-eg-gfrfts-h04 | C2: Does not respond to ping (since 032613) | D2: =VLOOKUP(A2,Chris!A2:A80,1,0) -> #N/A | E2: Decommisssioned? | F2: Recycled IP
A3: 10.213.24.224 | B3: ra-eg-gfrfts-h08 | C3: Does not respond to ping (since 032413) | D3: =VLOOKUP(A3,Chris!A3:A80,1,0) -> #N/A | E3: Decommisssioned? | F3: Recycled IP
A4: 10.213.24.230 | B4: ra-eg-gfrfts-h09 | C4: Does not respond to ping (since 032413) | D4: =VLOOKUP(A4,Chris!A4:A81,1,0) -> #N/A | E4: Decommisssioned? | F4: Recycled IP
A5: 10.213.24.231 | B5: ra-eg-gfrsql-h05 | C5: Does not respond to ping (since 032513) | D5: =VLOOKUP(A5,Chris!A5:A82,1,0) -> #N/A | E5: Decommisssioned? | F5: Recycled IP
A6: 10.213.24.232 | B6: ra-eg-gfrsql-h06 | C6: Does not respond to ping (since 032413) | D6: =VLOOKUP(A6,Chris!A6:A83,1,0) -> #N/A | E6: Decommisssioned? | F6: Recycled IP
A7: 192.168.250.131 | B7: aujpjptokdaiwcp-a01.tfn.com | C7: This IP's assignment information does not match DNS or ServiceManager (since 113012) | D7: =VLOOKUP(A7,Chris!A7:A84,1,0) -> 192.168.250.131
A8: 10.51.2.74 | B8: c711tmecmgs01.ten.thomsonreuters.com | C8: Does not respond to ping (since 032113) | D8: =VLOOKUP(A8,Chris!A8:A85,1,0) -> #N/A | E8: Decommissioned | F8: Recycled IP
A9: 10.51.5.18 | B9: C824XWEMPUB03 | C9: Does not respond to ping (since 032813) | D9: =VLOOKUP(A9,Chris!A9:A86,1,0) -> #N/A | E9: Shows as 10.51.8.10 | F9: Recycled IP
A10: 10.52.130.98 | B10: C265EZJGRCSNP | C10: Does not respond to ping (since 012913) | D10: =VLOOKUP(A10,Chris!A10:A87,1,0) -> 10.52.130.98
A11: 10.52.134.51 | B11: C111UBRLHUB03 | C11: Does not respond to ping (since 012913) | D11: =VLOOKUP(A11,Chris!A11:A88,1,0) -> 10.52.134.51
A12: 10.52.142.43 | B12: c720bvwcmgs01.ten.thomsonreuters.com | C12: Does not respond to ping (since 032113) | D12: =VLOOKUP(A12,Chris!A12:A89,1,0) -> #N/A | E12: Decommissioned | F12: Recycled IP
A13: 10.52.142.57 | B13: C828QPKQFS02 | C13: Does not respond to ping (since 021213) | D13: =VLOOKUP(A13,Chris!A13:A90,1,0) -> 10.52.142.57
A14: 10.59.176.75 | B14: RA-C888UXQMPUB01 | C14: Does not respond to ping (since 020513) | D14: =VLOOKUP(A14,Chris!A14:A91,1,0) -> 10.59.176.75
A15: 10.176.53.226 | B15: EG-J3RSQLQA-A01 | C15: Does not respond to ping (since 032913) | D15: =VLOOKUP(A15,Chris!A15:A92,1,0) -> #N/A | E15: Decommissioned | F15: Recycled IP
A16: 10.220.30.41 | B16: EG-SIRLBQ-B02C | C16: Does not respond to ping (since 032613) | D16: =VLOOKUP(A16,Chris!A25:A102,1,0) -> #N/A | F16: Recycled IP
A17: 10.204.64.96 | B17: c221dyhegnd06.tlr.thomson.com | C17: This IP's assignment information does not match DNS or ServiceManager (since 021213) | D17: =VLOOKUP(A17,Chris!A17:A94,1,0) -> #N/A
A18: 10.204.64.97 | B18: c494hqvegnd07.tlr.thomson.com | C18: This IP's assignment information does not match DNS or ServiceManager (since 021213) | D18: =VLOOKUP(A18,Chris!A18:A95,1,0) -> #N/A
A19: 10.52.130.59 | B19: C946WPW | C19: Does not respond to ping (since 032713) | D19: =VLOOKUP(A19,Chris!A33:A110,1,0) -> #N/A | E19: Decommissioned | F19: Recycled IP
A20: 10.52.130.61 | B20: C662YXU | C20: Does not respond to ping (since 032713) | D20: =VLOOKUP(A20,Chris!A34:A111,1,0) -> #N/A | E20: Decommissioned | F20: Recycled IP
A21: 10.221.253.190 | B21: EG-TFSSQL-A02 | C21: Does not respond to ping (since 032913) | D21: =VLOOKUP(A21,Chris!A36:A113,1,0) -> #N/A | E21: Decommissioned | F21: Recycled IP
A22: 10.204.32.129 | B22: c696xvjtftta.tlr.thomson.com | C22: This IP's assignment information does not match DNS or ServiceManager (since 051313) | D22: =VLOOKUP(A22,Chris!A16:A93,1,0) -> #N/A | E22: Change DNS
A23: 10.204.64.100 | B23: c290fscegnd10.tlr.thomson.com | C23: This IP's assignment information does not match DNS or ServiceManager (since 021113) | D23: =VLOOKUP(A23,Chris!A19:A96,1,0) -> #N/A | E23: Change DNS
A24: 10.215.31.40 | B24: c234qgj.ecom.tlrg.com | C24: This IP's assignment information does not match DNS or ServiceManager (since 032513) | D24: =VLOOKUP(A24,Chris!A24:A101,1,0) -> #N/A
A25: 10.204.66.48 | B25: testserver14 | C25: Does not respond to ping (since 032513) | D25: =VLOOKUP(A25,Chris!A20:A97,1,0) -> #N/A
A26: 10.205.69.10 | B26: boardlinkdav-dev.accelus.com | C26: This IP's assignment information does not match DNS or ServiceManager (since 062713) | D26: =VLOOKUP(A26,Chris!A21:A98,1,0) -> #N/A | E26: No SM
A27: 10.206.16.3 | B27: powerapp.int.westgroup.com | C27: This IP's assignment information does not match DNS or ServiceManager (since 070613) | D27: =VLOOKUP(A27,Chris!A22:A99,1,0) -> #N/A | E27: No SM
A28: 10.206.16.214 | B28: cubiscan-test.int.westgroup.com | C28: This IP's assignment information does not match DNS or ServiceManager (since 070113) | D28: =VLOOKUP(A28,Chris!A23:A100,1,0) -> #N/A | E28: No SM
A29: 163.231.83.217 | B29: pfsso.int.thomsonreuters.com | C29: Does not respond to ping (since 011213) | D29: =VLOOKUP(A29,Chris!A29:A106,1,0) -> 163.231.83.217
A30: 163.231.94.89 | B30: eg-hdsadm-a04.int.westgroup.com | C30: Does not respond to ping (since 030313) | D30: =VLOOKUP(A30,Chris!A30:A107,1,0) -> 163.231.94.89
A31: 163.231.99.40 | B31: koro | C31: Does not respond to ping (since 020413) | D31: =VLOOKUP(A31,Chris!A31:A108,1,0) -> 163.231.99.40
A32: 10.51.0.21 | B32: pvdr.int.thomsonreuters.com | C32: This IP's assignment information does not match DNS or ServiceManager (since 050713) | D32: =VLOOKUP(A32,Chris!A32:A109,1,0) -> 10.51.0.21
A33: 10.225.4.136 | B33: tss1vdev0104 | C33: Does not respond to ping (since 120712) | D33: =VLOOKUP(A33,Chris!A26:A103,1,0) -> #N/A
A34: 10.226.50.178 | B34: boardlinkservices-qa.accelus.eu | C34: This IP's assignment information does not match DNS or ServiceManager (since 070313) | D34: =VLOOKUP(A34,Chris!A27:A104,1,0) -> #N/A | E34: No SM
A35: 10.226.50.179 | B35: boardlinkdav-qa.accelus.eu | C35: This IP's assignment information does not match DNS or ServiceManager (since 070313) | D35: =VLOOKUP(A35,Chris!A28:A105,1,0) -> #N/A | E35: No SM
A36: 10.206.19.107 | B36: pvcluster.int.thomsonreuters.com | C36: This IP's assignment information does not match DNS or ServiceManager (since 050713) | D36: =VLOOKUP(A36,Chris!A35:A112,1,0) -> #N/A

Sheet Zipper 7-16
A1: IPAddress | B1: Hostname | C1: Description | D1: Compared | E1: Notes | F1: Action Taken
A2: 10.51.1.10 | B2: C239DYHEXOLP2 | C2: This IP's assignment information does not match DNS or ServiceManager (since 071413) | D2: =VLOOKUP(A2,Chris!A3:A80,1,0) -> #N/A | E2: Decommission | F2: Recycled IP
A3: 10.51.1.11 | B3: C534JRVEXSQL2 | C3: This IP's assignment information does not match DNS or ServiceManager (since 071313) | D3: =VLOOKUP(A3,Chris!A4:A80,1,0) -> 10.51.1.11 | E3: Decommission | F3: Recycled IP
A4: 10.51.8.80 | B4: C111WFXEMBX73 | C4: Does not respond to ping (since 040413) | D4: =VLOOKUP(A4,Chris!A5:A81,1,0) -> #N/A | E4: No SM Record
A5: 10.52.130.98 | B5: C265EZJGRCSNP | C5: Does not respond to ping (since 012913) | D5: =VLOOKUP(A5,Chris!A6:A82,1,0) -> 10.52.130.98
A6: 10.52.134.51 | B6: C111UBRLHUB03 | C6: Does not respond to ping (since 012913) | D6: =VLOOKUP(A6,Chris!A7:A83,1,0) -> 10.52.134.51
A7: 10.52.142.39 | B7: C382VBHAVNS01 | C7: Does not respond to ping (since 040513) | D7: =VLOOKUP(A7,Chris!A8:A84,1,0) -> #N/A | E7: Contact Windows Tcash
A8: 10.52.142.40 | B8: C531ZENAVNS02 | C8: Does not respond to ping (since 040513) | D8: =VLOOKUP(A8,Chris!A9:A85,1,0) -> #N/A | E8: New IP Address | F8: Recycled IP
A9: 10.52.142.41 | B9: C701SMEAVOS01 | C9: Does not respond to ping (since 040513) | D9: =VLOOKUP(A9,Chris!A10:A86,1,0) -> #N/A | E9: New IP Address | F9: Recycled IP
A10: 10.52.142.57 | B10: C828QPKQFS02 | C10: Does not respond to ping (since 021213) | D10: =VLOOKUP(A10,Chris!A11:A87,1,0) -> 10.52.142.57
A11: 10.59.176.75 | B11: RA-C888UXQMPUB01 | C11: Does not respond to ping (since 020513) | D11: =VLOOKUP(A11,Chris!A12:A88,1,0) -> 10.59.176.75
A12: 10.204.64.96 | B12: c221dyhegnd06.tlr.thomson.com | C12: This IP's assignment information does not match DNS or ServiceManager (since 021213) | D12: =VLOOKUP(A12,Chris!A13:A89,1,0) -> 10.204.64.96
A13: 10.204.64.97 | B13: c494hqvegnd07.tlr.thomson.com | C13: This IP's assignment information does not match DNS or ServiceManager (since 021213) | D13: =VLOOKUP(A13,Chris!A14:A90,1,0) -> 10.204.64.97
A14: 10.204.66.48 | B14: testserver14 | C14: Does not respond to ping (since 032513) | D14: =VLOOKUP(A14,Chris!A15:A91,1,0) -> #N/A
A15: 10.205.50.25 | B15: C111TVM | C15: This IP's assignment information does not match DNS or ServiceManager (since 071313) | D15: =VLOOKUP(A15,Chris!A16:A92,1,0) -> #N/A | E15: Decommissioned | F15: Recycled IP
A16: 10.205.69.10 | B16: boardlinkdav-dev.accelus.com | C16: This IP's assignment information does not match DNS or ServiceManager (since 062713) | D16: =VLOOKUP(A16,Chris!A17:A93,1,0) -> #N/A | E16: Contact Joe Bruns - Decommission | F16: Recycled IP
A17: 10.206.16.3 | B17: powerapp.int.westgroup.com | C17: This IP's assignment information does not match DNS or ServiceManager (since 070613) | D17: =VLOOKUP(A17,Chris!A18:A94,1,0) -> #N/A | E17: C111DUT / Melissa
A18: 10.206.169.10 | B18: N-C111VFSPMBS09 | C18: Does not respond to ping (since 040613) | D18: =VLOOKUP(A18,Chris!A19:A95,1,0) -> #N/A | E18: Decommissioned | F18: Recycled IP
A19: 10.206.169.11 | B19: N-C111XHUPMBS10 | C19: Does not respond to ping (since 040613) | D19: =VLOOKUP(A19,Chris!A20:A96,1,0) -> #N/A | E19: Decommissioned | F19: Recycled IP
A20: 10.206.169.18 | B20: C111DJWHMBX77 | C20: Does not respond to ping (since 040613) | D20: =VLOOKUP(A20,Chris!A21:A97,1,0) -> #N/A | E20: New IP Address | F20: Recycled IP
A21: 10.215.31.40 | B21: c234qgj.ecom.tlrg.com | C21: This IP's assignment information does not match DNS or ServiceManager (since 032513) | D21: =VLOOKUP(A21,Chris!A22:A98,1,0) -> 10.215.31.40
A22: 10.220.30.41 | B22: EG-SIRLBQ-B02C | C22: Does not respond to ping (since 032613) | D22: =VLOOKUP(A22,Chris!A23:A99,1,0) -> #N/A | E22: Decommissioned | F22: Recycled IP
A23: 10.220.51.144 | B23: RA-EG-CRMQA-B23 | C23: Does not respond to ping (since 040613) | D23: =VLOOKUP(A23,Chris!A24:A100,1,0) -> #N/A | E23: Decommissioned | F23: Recycled IP
A24: 10.220.172.1 | B24: c111vtv | C24: Does not respond to ping (since 040213) | D24: =VLOOKUP(A24,Chris!A25:A101,1,0) -> #N/A | E24: Contact Nick Robbins - ReDeployed | F24: Recycled IP
A25: 10.221.250.97 | B25: RA-EG-CRM-B25 | C25: Does not respond to ping (since 040613) | D25: =VLOOKUP(A25,Chris!A26:A102,1,0) -> #N/A | F25: Recycled IP
A26: 10.225.4.136 | B26: tss1vdev0104 | C26: Does not respond to ping (since 120712) | D26: =VLOOKUP(A26,Chris!A27:A103,1,0) -> #N/A | F26: Recycled IP
A27: 10.226.50.178 | B27: boardlinkservices-qa.accelus.eu | C27: This IP's assignment information does not match DNS or ServiceManager (since 070313) | D27: =VLOOKUP(A27,Chris!A28:A104,1,0) -> #N/A
A28: 10.226.50.179 | B28: boardlinkdav-qa.accelus.eu | C28: This IP's assignment information does not match DNS or ServiceManager (since 070313) | D28: =VLOOKUP(A28,Chris!A29:A105,1,0) -> #N/A
A29: 163.231.23.4 | B29: EAGE-ERFPMBS14 | C29: Does not respond to ping (since 040613) | D29: =VLOOKUP(A29,Chris!A30:A106,1,0) -> #N/A | E29: Decommissioned | F29: Recycled IP
A30: 163.231.23.35 | B30: EAGE-ERFPMBS04 | C30: Does not respond to ping (since 040613) | D30: =VLOOKUP(A30,Chris!A31:A107,1,0) -> #N/A | E30: Decommissioned | F30: Recycled IP
A31: 163.231.23.53 | B31: c111wfxembx73 | C31: Does not respond to ping (since 040613) | D31: =VLOOKUP(A31,Chris!A32:A108,1,0) -> #N/A
A32: 163.231.23.68 | B32: EAGE-ERFPMBS06 | C32: Does not respond to ping (since 040613) | D32: =VLOOKUP(A32,Chris!A33:A109,1,0) -> #N/A | E32: Decommissioned | F32: Recycled IP
A33: 163.231.29.200 | B33: C111VFSPMBS09 | C33: Does not respond to ping (since 040613) | D33: =VLOOKUP(A33,Chris!A34:A110,1,0) -> #N/A | E33: Decommissioned | F33: Recycled IP
A34: 163.231.29.204 | B34: C111XHUPMBS10 | C34: Does not respond to ping (since 040613) | D34: =VLOOKUP(A34,Chris!A35:A111,1,0) -> #N/A | E34: Decommissioned | F34: Recycled IP
A35: 163.231.29.211 | B35: C111DJWHMBX77 | C35: Does not respond to ping (since 040613) | D35: =VLOOKUP(A35,Chris!A36:A112,1,0) -> #N/A | E35: New IP Address | F35: Recycled IP
A36: 163.231.31.136 | B36: C111DQHXBES20 | C36: Does not respond to ping (since 040113) | D36: =VLOOKUP(A36,Chris!A37:A113,1,0) -> #N/A | F36: Recycled IP
A37: 163.231.31.137 | B37: C111GRHXBES21 | C37: Does not respond to ping (since 040113) | D37: =VLOOKUP(A37,Chris!A38:A114,1,0) -> #N/A | E37: V2V | F37: Recycled IP
A38: 163.231.83.217 | B38: pfsso.int.thomsonreuters.com | C38: Does not respond to ping (since 011213) | D38: =VLOOKUP(A38,Chris!A39:A115,1,0) -> 163.231.83.217
A39: 163.231.94.89 | B39: eg-hdsadm-a04.int.westgroup.com | C39: Does not respond to ping (since 030313) | D39: =VLOOKUP(A39,Chris!A40:A116,1,0) -> 163.231.94.89
A40: 163.231.99.40 | B40: koro | C40: Does not respond to ping (since 020413) | D40: =VLOOKUP(A40,Chris!A41:A117,1,0) -> 163.231.99.40
...

Sheet Zipper 7-23
A1: IPAddress | B1: Hostname | C1: Description | D1: Compared | E1: Notes | F1: Action Taken
A2: 10.51.1.11 | B2: C534JRVEXSQL2 | C2: This IP's assignment information does not match DNS or ServiceManager (since 071313)
A3: 10.51.2.64 | B3: C274CJPQADM01 | C3: Does not respond to ping (since 041213)
A4: 10.51.2.65 | B4: C434FPTSQL02 | C4: Does not respond to ping (since 041113)
A5: 10.51.2.68 | B5: c145dxravcm02 | C5: Does not respond to ping (since 040713)
A6: 10.51.2.69 | B6: c332hbvavns02 | C6: Does not respond to ping (since 040713)
A7: 10.51.2.71 | B7: c169nfhavos01 | C7: Does not respond to ping (since 040713)
A8: 10.51.2.86 | B8: c064kcefsmo01 | C8: Does not respond to ping (since 040713)
A9: 10.51.2.88 | B9: c506nfzprnt01 | C9: Does not respond to ping (since 040713)
A10: 10.51.2.90 | B10: c212pgjtsad01 | C10: Does not respond to ping (since 040713)
A11: 10.51.2.92 | B11: c048ntzqfs02 | C11: Does not respond to ping (since 040713)
A12: 10.51.2.95 | B12: c087xejcmsql1 | C12: Does not respond to ping (since 041113)
A13: 10.51.8.80 | B13: C111WFXEMBX73 | C13: Does not respond to ping (since 040413)
... A26: 10.52.142.55 | B26: C304TZFQFS01 | C26: Does not respond to ping (since 041113)
A27: 10.52.142.56 | B27: C828QPKQFS02 | C27: Does not respond to ping (since 041113) | F27: Recycled IP?
A28: 10.52.142.57 | B28: C828QPKQFS02 | C28: Does not respond to ping (since 021213) | F28: Recycled IP?
A29: 10.59.176.75 | B29: RA-C888UXQMPUB01 | C29: Does not respond to ping (since 020513) | E29: Decommissioned | F29: Recycled IP
A30: 10.204.64.96 | B30: c221dyhegnd06.tlr.thomson.com | C30: This IP's assignment information does not match DNS or ServiceManager (since 021213) | E30: Device Name was not consistant | F30: Changed Device Name banana
A31: 10.204.64.97 | B31: c494hqvegnd07.tlr.thomson.com | C31: This IP's assignment information does not match DNS or ServiceManager (since 021213) | E31: Device Name was not consistant | F31: Changed Device Name banana
A32: 10.204.66.48 | B32: testserver14 | C32: Does not respond to ping (since 032513) | E32: Decommissioned | F32: Recycled IP
A33: 10.206.169.14 | B33: C111BNMHMBX57 | C33: Does not respond to ping (since 040913) | E33: New IP | F33: Recycled IP
A34: 10.213.40.190 | B34: RA-C111CYXEMBX53 | C34: Does not respond to ping (since 040913) | E34: Decommissioned | F34: Recycled IP
A35: 10.215.31.40 | B35: c234qgj.ecom.tlrg.com | C35: This IP's assignment information does not match DNS or ServiceManager (since 032513) | E35: Windows TCASH
A36: 10.216.64.4 | B36: EG-TAWEB-A03 | C36: Does not respond to ping (since 040813) | E36: V2V | F36: Recycled IP
A37: 10.216.64.9 | B37: EG-TAWEB-A02 | C37: Does not respond to ping (since 040813) | E37: V2V | F37: Recycled IP
A38: 10.216.64.11 | B38: eg-taweb-a02 | C38: Does not respond to ping (since 040813) | E38: V2V | F38: Recycled IP
A39: 10.216.64.103 | B39: EG-TAWEB-A03 | C39: Does not respond to ping (since 040813) | E39: New IP Address | F39: Recycled IP
A40: 10.221.253.182 | B40: RA-EG-CRMQA-A22 | C40: Does not respond to ping (since 040913) | E40: Retired | F40: Recycled IP
A41: 10.221.254.146 | B41: EG-CRM-A24 | C41: Does not respond to ping (since 040913) | E41: Decommissioned | F41: Recycled IP
A42: 163.231.21.34 | B42: C111EJEHBES20 | C42: Does not respond to ping (since 041213) | E42: IP address shows 10.51.5.84 | F42: Recycled IP
A43: 163.231.23.51 | B43: c111cyxembx53 | C43: Does not respond to ping (since 040913) | E43: New IP Address | F43: Recycled IP
A44: 163.231.23.53 | B44: c111wfxembx73 | C44: Does not respond to ping (since 040613) | E44: New IP Address | F44: Recycled IP
A45: 163.231.29.209 | B45: C111BNMHMBX57 | C45: Does not respond to ping (since 040913) | E45: New IP Address | F45: Recycled IP
A46: 163.231.99.40 | B46: koro | C46: Does not respond to ping (since 020413) | E46: New IP address | F46: Recycled IP Address
A47: 10.220.48.140 | B47: RA-EG-CRMSQLDV-B13 | C47: Does not respond to ping (since 041213) | E47: Decommissioned | F47: Recycled IP
A48: 10.221.241.206 | B48: EG-CTRX-B34 | C48: Does not respond to ping (since 040613) | F48: Recycled IP
A49: 10.221.253.123 | B49: EG-CRMQA-A20 | C49: Does not respond to ping (since 041113) | E49: Decommission | F49: Recycled IP
A50: 192.168.250.131 | B50: aujpjptokdaiwcp-a01.tfn.com | C50: This IP's assignment information does not match DNS or ServiceManager (since 113012) | F50: Recycled IP
A51: 10.206.16.3 | B51: powerapp.int.westgroup.com | C51: This IP's assignment information does not match DNS or ServiceManager (since 070613) | E51: Windows TCASH | F51: Chad Brochill
A52: 10.206.16.20 | B52: rsgprod-test.int.westgroup.com | C52: This IP's assignment information does not match DNS or ServiceManager (since 071213) | E52: Windows TCASH | F52: Chad Brochill
...

Sheet Zipper 7-30
A1: IPAddress | B1: Hostname | C1: Description | D1: Compared | E1: Notes | F1: Action Taken
A2: 10.213.24.221 | B2: ra-eg-gfrsql-h01 | C2: Does not respond to ping (since 041713) | D2: =VLOOKUP(B2,'Zipper 7-23'!B:B,1,0) -> #N/A | E2: Renamed | F2: Recycled IP
A3: 10.213.24.222 | B3: ra-eg-gfrsql-h02 | C3: Does not respond to ping (since 041613) | D3: =VLOOKUP(B3,'Zipper 7-23'!B:B,1,0) -> #N/A | E3: Renamed | F3: Recycled IP
A4: 10.213.24.226 | B4: ra-eg-gfrsql-h03 | C4: Does not respond to ping (since 041613) | D4: =VLOOKUP(B4,'Zipper 7-23'!B:B,1,0) -> #N/A | E4: Renamed | F4: Recycled IP
A5: 10.213.24.227 | B5: ra-eg-gfrsql-h04 | C5: Does not respond to ping (since 041613) | D5: =VLOOKUP(B5,'Zipper 7-23'!B:B,1,0) -> #N/A | E5: Renamed | F5: Recycled IP
A6: 192.168.250.131 | B6: aujpjptokdaiwcp-a01.tfn.com | C6: This IP's assignment information does not match DNS or ServiceManager (since 113012) | D6: =VLOOKUP(B6,'Zipper 7-23'!B:B,1,0) -> aujpjptokdaiwcp-a01.tfn.com | E6: Contacted ITS-MDS-DIR
A7: 10.51.0.21 | B7: pvdr.int.thomsonreuters.com | C7: This IP's assignment information does not match DNS or ServiceManager (since 050713) | D7: =VLOOKUP(B7,'Zipper 7-23'!B:B,1,0) -> pvdr.int.thomsonreuters.com | E7: Windows TCASH | F7: Chad Brochill
A8: 10.51.7.27 | B8: stargazerc1.tlr.thomson.com | C8: This IP's assignment information does not match DNS or ServiceManager (since 072613) | D8: =VLOOKUP(B8,'Zipper 7-23'!B:B,1,0) -> #N/A | E8: Mike Schmidt | F8: No Action Taken
A9: 10.51.7.28 | B9: stargazerc2.tlr.thomson.com | C9: This IP's assignment information does not match DNS or ServiceManager (since 072613) | D9: =VLOOKUP(B9,'Zipper 7-23'!B:B,1,0) -> #N/A | E9: Mike Schmidt | F9: No Action Taken
A10: 10.51.7.29 | B10: stargazerc3.tlr.thomson.com | C10: This IP's assignment information does not match DNS or ServiceManager (since 072613) | D10: =VLOOKUP(B10,'Zipper 7-23'!B:B,1,0) -> #N/A | E10: Mike Schmidt | F10: No Action Taken
A11: 10.52.128.54 | B11: C111CRW | C11: Does not respond to ping (since 041713) | D11: =VLOOKUP(B11,'Zipper 7-23'!B:B,1,0) -> #N/A | E11: Decommission | F11: Recycled IP
A12: 10.52.128.64 | B12: C734TJS | C12: Does not respond to ping (since 041713) | D12: =VLOOKUP(B12,'Zipper 7-23'!B:B,1,0) -> #N/A | E12: Decommission | F12: Recycled IP
A13: 10.52.128.65 | B13: C654TPJ | C13: Does not respond to ping (since 041713) | D13: =VLOOKUP(B13,'Zipper 7-23'!B:B,1,0) -> #N/A | E13: Decommission | F13: Recycled IP
A14: 10.52.133.64 | B14: C734TJS | C14: Does not respond to ping (since 041713) | D14: =VLOOKUP(B14,'Zipper 7-23'!B:B,1,0) -> #N/A | E14: Decommission | F14: Recycled IP
A15: 10.52.133.65 | B15: C654TPJ | C15: Does not respond to ping (since 041713) | D15: =VLOOKUP(B15,'Zipper 7-23'!B:B,1,0) -> #N/A | E15: Decommission | F15: Recycled IP
A16: 10.206.19.107 | B16: pvcluster.int.thomsonreuters.com | C16: This IP's assignment information does not match DNS or ServiceManager (since 050713) | D16: =VLOOKUP(B16,'Zipper 7-23'!B:B,1,0) -> pvcluster.int.thomsonreuters.com | E16: Windows TCASH | F16: Chad Brochill
A17: 10.220.20.141 | B17: Eg-Eltvmdv-B12 | C17: Does not respond to ping (since 031213) | D17: =VLOOKUP(B17,'Zipper 7-23'!B:B,1,0) -> #N/A | E17: Decommission | F17: Recycled IP
A18: 10.220.20.142 | B18: eg-eltvmdv-b13 | C18: Does not respond to ping (since 031213) | D18: =VLOOKUP(B18,'Zipper 7-23'!B:B,1,0) -> #N/A | E18: Decommission | F18: Recycled IP
... A20: 10.220.20.144 | B20: Eg-Eltvmdv-B15 | C20: Does not respond to ping (since 031213) | D20: =VLOOKUP(B20,'Zipper 7-23'!B:B,1,0) -> #N/A | E20: Decommission | F20: Recycled IP
A21: 10.51.1.10 | C21: This IP is apparently in use, but it has not been assigned (since 072213) | D21: =VLOOKUP(B21,'Zipper 7-23'!B:B,1,0) -> #N/A | E21: No Information within Banana | F21: Modified Banana record
A22: 10.51.2.66 | B22: c925wraavcm01 | C22: Does not respond to ping (since 041713) | D22: =VLOOKUP(B22,'Zipper 7-23'!B:B,1,0) -> #N/A | E22: Server Moved - New IP | F22: Recycled IP
A23: 10.51.2.67 | B23: c932yskavcm03 | C23: Does not respond to ping (since 041713) | D23: =VLOOKUP(B23,'Zipper 7-23'!B:B,1,0) -> #N/A | E23: Server Moved - New IP | F23: Recycled IP
A24: 10.51.2.70 | B24: c995ksyavns01 | C24: Does not respond to ping (since 041713) | D24: =VLOOKUP(B24,'Zipper 7-23'!B:B,1,0) -> #N/A | E24: Server Moved - New IP | F24: Recycled IP
A25: 10.51.2.72 | B25: c276rhkavos02 | C25: Does not respond to ping (since 041613) | D25: =VLOOKUP(B25,'Zipper 7-23'!B:B,1,0) -> #N/A | E25: Server Moved - New IP | F25: Recycled IP
A26: 10.51.2.73 | B26: c602qjcavos02 | C26: Does not respond to ping (since 041613) | D26: =VLOOKUP(B26,'Zipper 7-23'!B:B,1,0) -> #N/A | E26: Server Moved - New IP | F26: Recycled IP
A27: 10.51.2.75 | B27: c693auwcmmp01 | C27: Does not respond to ping (since 041613) | D27: =VLOOKUP(B27,'Zipper 7-23'!B:B,1,0) -> #N/A | E27: Server Moved - New IP | F27: Recycled IP
A28: 10.51.2.76 | B28: c900xrjcmpp01 | C28: Does not respond to ping (since 041713) | D28: =VLOOKUP(B28,'Zipper 7-23'!B:B,1,0) -> #N/A | E28: Server Moved - New IP | F28: Recycled IP
A29: 10.51.2.77 | B29: c136megcmpr01 | C29: Does not respond to ping (since 041613) | D29: =VLOOKUP(B29,'Zipper 7-23'!B:B,1,0) -> #N/A | E29: Server Moved - New IP | F29: Recycled IP
A30: 10.51.2.78 | B30: c294gaucmsp01 | C30: Does not respond to ping (since 041613) | D30: =VLOOKUP(B30,'Zipper 7-23'!B:B,1,0) -> #N/A | E30: Server Moved - New IP | F30: Recycled IP
A31: 10.51.2.79 | B31: c630bgqcmsp02 | C31: Does not respond to ping (since 041613) | D31: =VLOOKUP(B31,'Zipper 7-23'!B:B,1,0) -> #N/A | E31: Server Moved - New IP | F31: Recycled IP
A32: 10.51.2.80 | B32: c562jswcmup01 | C32: Does not respond to ping (since 041613) | D32: =VLOOKUP(B32,'Zipper 7-23'!B:B,1,0) -> #N/A | E32: Server Moved - New IP | F32: Recycled IP
